<?xml version="1.0" encoding="utf-8"?>
<!-- This URDF was automatically created by SolidWorks to URDF Exporter! Originally created by Stephen Brawner (brawner@gmail.com) 
     Commit Version: 1.6.0-1-g15f4949  Build Version: 1.6.7594.29634
     For more information, please see http://wiki.ros.org/sw_urdf_exporter -->
<robot name="cr5_robot">
  <!-- Gazebo-only anchor: the physical CR5 base is bolted to the surface. -->
  <link name="world" />

  <link name="dummy_link">
    <inertial>
      <origin xyz="0 0 0" rpy="0 0 0" />
      <mass value="0.001" />
      <inertia
        ixx="1e-6"
        ixy="0"
        ixz="0"
        iyy="1e-6"
        iyz="0"
        izz="1e-6" />
    </inertial>
  </link>
  <link name="base_link">
    <inertial>
      <origin xyz="0 0 0.035" rpy="0 0 0" />
      <mass value="5.0" />
      <inertia ixx="0.05" ixy="0" ixz="0" iyy="0.05" iyz="0" izz="0.05" />
    </inertial>
    <visual>
      <origin xyz="0 0 0" rpy="0 0 0" />
      <geometry>
        <mesh filename="package://dobot_description/meshes/cr5/base_link.dae" />
      </geometry>
      <material
        name="">
        <color rgba="0 0 0 1" />
      </material>
    </visual>
    <collision>
      <origin xyz="0 0 0.035" rpy="0 0 0" />
      <geometry>
        <cylinder radius="0.13" length="0.07" />
      </geometry>
    </collision>
  </link>

  <joint name="world_fixed" type="fixed">
    <parent link="world" />
    <child link="base_link" />
    <origin xyz="0 0 0" rpy="0 0 0" />
  </joint>

  <joint name="dummy_joint" type="fixed">
    <parent link="base_link" />
    <child  link="dummy_link" />
  </joint>


  <link  name="Link1">
    <inertial>
      <origin xyz="0 0 -0.01" rpy="0 0 0" />
      <mass value="2.0" />
      <inertia ixx="0.02" ixy="0" ixz="0" iyy="0.02" iyz="0" izz="0.02" />
    </inertial>
    <visual>
      <origin xyz="0 0 0" rpy="0 0 0" />
      <geometry>
        <mesh filename="package://dobot_description/meshes/cr5/Link1.dae" />
      </geometry>
      <material
        name="">
        <color rgba="1 1 1 1" />
      </material>
    </visual>
    <collision>
      <origin xyz="0 0 -0.01" rpy="0 0 0" />
      <geometry>
        <cylinder radius="0.10" length="0.16" />
      </geometry>
    </collision>
  </link>

  <joint name="joint1" type="revolute">
    <origin xyz="0 0 0.147" rpy="0 0 0" />
    <parent link="base_link" />
    <child link="Link1" />
    <axis xyz="0 0 1" />
    <dynamics damping="1.0" friction="0.05" />
    <limit lower="-12.5664" upper="12.5664" effort="200" velocity="1.5" />
  </joint>

  <link name="Link2">
    <inertial>
      <origin xyz="-0.215 0 0.14" rpy="0 0 0" />
      <mass value="5.5" />
      <inertia ixx="0.08" ixy="0" ixz="0" iyy="0.08" iyz="0" izz="0.08" />
    </inertial>
    <visual>
      <origin xyz="0 0 0" rpy="0 0 0" />
      <geometry>
        <mesh filename="package://dobot_description/meshes/cr5/Link2.dae" />
      </geometry>
      <material
        name="">
        <color rgba="1 1 1 1" />
      </material>
    </visual>
    <collision>
      <origin xyz="-0.215 0 0.14" rpy="0 0 0" />
      <geometry>
        <box size="0.46 0.12 0.16" />
      </geometry>
    </collision>
  </link>

  <joint name="joint2" type="revolute">
    <origin xyz="0 0 0" rpy="1.5708 1.5708 0" />
    <parent link="Link1" />
    <child  link="Link2" />
    <axis xyz="0 0 1" />
    <dynamics damping="2.0" friction="0.1" />
    <limit lower="-12.5664" upper="12.5664" effort="300" velocity="1.5" />
  </joint>

  <link name="Link3">
    <inertial>
      <origin xyz="-0.18 0 0.03" rpy="0 0 0" />
      <mass value="3.0" />
      <inertia ixx="0.05" ixy="0" ixz="0" iyy="0.05" iyz="0" izz="0.05" />
    </inertial>
    <visual>
      <origin xyz="0 0 0" rpy="0 0 0" />
      <geometry>
        <mesh filename="package://dobot_description/meshes/cr5/Link3.dae" />
      </geometry>
      <material
        name="">
        <color rgba="1 1 1 1" />
      </material>
    </visual>
    <collision>
      <origin xyz="-0.18 0 0.03"  rpy="0 0 0" />
      <geometry>
        <box size="0.40 0.10 0.12" />
      </geometry>
    </collision>
  </link>

  <joint name="joint3" type="revolute">
    <origin xyz="-0.427 0 0" rpy="0 0 0" />
    <parent link="Link2" />
    <child link="Link3" />
    <axis  xyz="0 0 1" />
    <dynamics damping="2.0" friction="0.1" />
    <limit lower="-12.5664"  upper="12.5664"  effort="220" velocity="1.5" />
  </joint>

  <link name="Link4">
    <inertial>
      <origin xyz="0 -0.005 0" rpy="0 0 0" />
      <mass value="1.0" />
      <inertia ixx="0.01" ixy="0" ixz="0" iyy="0.01" iyz="0" izz="0.01" />
    </inertial>
    <visual>
      <origin xyz="0 0 0" rpy="0 0 0" />
      <geometry>
        <mesh filename="package://dobot_description/meshes/cr5/Link4.dae" />
      </geometry>
      <material name="">
        <color rgba="1 1 1 1" />
      </material>
    </visual>
    <collision>
      <origin xyz="0 -0.005 0" rpy="0 0 0" />
      <geometry>
        <box size="0.12 0.10 0.12" />
      </geometry>
    </collision>
  </link>

  <joint name="joint4" type="revolute">
    <origin xyz="-0.357 0 0.141" rpy="0 0 -1.5708" />
    <parent link="Link3" />
    <child link="Link4" />
    <axis xyz="0 0 1" />
    <dynamics damping="5.0" friction="0.2" />
    <limit lower="-12.5664" upper="12.5664" effort="80" velocity="1.0" />
  </joint>
  <link
    name="Link5">
    <inertial>
      <origin xyz="0 -0.04 0" rpy="0 0 0" />
      <mass value="1.0" />
      <inertia ixx="0.01" ixy="0" ixz="0" iyy="0.01" iyz="0" izz="0.01" />
    </inertial>
    <visual>
      <origin xyz="0 0 0" rpy="0 0 0" />
      <geometry>
        <mesh filename="package://dobot_description/meshes/cr5/Link5.dae" />
      </geometry>
      <material name="">
        <color rgba="1 1 1 1" />
      </material>
    </visual>
    <collision>
      <origin xyz="0 -0.04 0" rpy="0 0 0" />
      <geometry>
        <box size="0.10 0.12 0.10" />
      </geometry>
    </collision>
  </link>

  <joint name="joint5" type="revolute">
    <origin xyz="0 -0.116 0" rpy="1.5708 0 0" />
    <parent link="Link4" />
    <child link="Link5" />
    <axis xyz="0 0 1" />
    <dynamics damping="5.0" friction="0.2" />
    <limit lower="-12.5664" upper="12.5664" effort="80" velocity="1.0" />
  </joint>

  <link name="Link6">
    <inertial>
      <origin xyz="0 0 -0.02" rpy="0 0 0" />
      <mass value="0.5" />
      <inertia ixx="0.005" ixy="0" ixz="0" iyy="0.005" iyz="0" izz="0.005" />
    </inertial>
    <visual>
      <origin xyz="0 0 0" rpy="0 0 0" />
      <geometry>
        <mesh filename="package://dobot_description/meshes/cr5/Link6.dae" />
      </geometry>
      <material name="">
        <color rgba="1 1 1 1" />
      </material>
    </visual>
    <collision>
      <origin xyz="0 0 -0.02" rpy="0 0 0" />
      <geometry>
        <cylinder radius="0.045" length="0.08" />
      </geometry>
    </collision>
  </link>

  <joint name="joint6" type="revolute">
    <origin xyz="0 0.105 0"  rpy="-1.5708 0 0" />
    <parent link="Link5" />
    <child link="Link6" />
    <axis xyz="0 0 1" />
    <dynamics damping="10.0" friction="0.5" />
    <limit lower="-12.5664" upper="12.5664" effort="40" velocity="1.0" />
  </joint>

  <!-- Gazebo ROS Control effort interfaces for the six actuated CR5 joints. -->
  <transmission name="joint1_trans">
    <type>transmission_interface/SimpleTransmission</type>
    <joint name="joint1">
      <hardwareInterface>hardware_interface/EffortJointInterface</hardwareInterface>
    </joint>
    <actuator name="joint1_motor">
      <hardwareInterface>hardware_interface/EffortJointInterface</hardwareInterface>
      <mechanicalReduction>1</mechanicalReduction>
    </actuator>
  </transmission>

  <transmission name="joint2_trans">
    <type>transmission_interface/SimpleTransmission</type>
    <joint name="joint2">
      <hardwareInterface>hardware_interface/EffortJointInterface</hardwareInterface>
    </joint>
    <actuator name="joint2_motor">
      <hardwareInterface>hardware_interface/EffortJointInterface</hardwareInterface>
      <mechanicalReduction>1</mechanicalReduction>
    </actuator>
  </transmission>

  <transmission name="joint3_trans">
    <type>transmission_interface/SimpleTransmission</type>
    <joint name="joint3">
      <hardwareInterface>hardware_interface/EffortJointInterface</hardwareInterface>
    </joint>
    <actuator name="joint3_motor">
      <hardwareInterface>hardware_interface/EffortJointInterface</hardwareInterface>
      <mechanicalReduction>1</mechanicalReduction>
    </actuator>
  </transmission>

  <transmission name="joint4_trans">
    <type>transmission_interface/SimpleTransmission</type>
    <joint name="joint4">
      <hardwareInterface>hardware_interface/EffortJointInterface</hardwareInterface>
    </joint>
    <actuator name="joint4_motor">
      <hardwareInterface>hardware_interface/EffortJointInterface</hardwareInterface>
      <mechanicalReduction>1</mechanicalReduction>
    </actuator>
  </transmission>

  <transmission name="joint5_trans">
    <type>transmission_interface/SimpleTransmission</type>
    <joint name="joint5">
      <hardwareInterface>hardware_interface/EffortJointInterface</hardwareInterface>
    </joint>
    <actuator name="joint5_motor">
      <hardwareInterface>hardware_interface/EffortJointInterface</hardwareInterface>
      <mechanicalReduction>1</mechanicalReduction>
    </actuator>
  </transmission>

  <transmission name="joint6_trans">
    <type>transmission_interface/SimpleTransmission</type>
    <joint name="joint6">
      <hardwareInterface>hardware_interface/EffortJointInterface</hardwareInterface>
    </joint>
    <actuator name="joint6_motor">
      <hardwareInterface>hardware_interface/EffortJointInterface</hardwareInterface>
      <mechanicalReduction>1</mechanicalReduction>
    </actuator>
  </transmission>

  <gazebo>
    <plugin name="gazebo_ros_control" filename="libgazebo_ros_control.so">
      <robotNamespace>/</robotNamespace>
    </plugin>
  </gazebo>

  <!-- Wrist-mounted RGB-D camera for Gazebo/ROS viewing -->
  <link name="wrist_rgbd_camera_link">
    <visual>
      <origin xyz="0 0 0" rpy="0 0 0"/>
      <geometry>
        <box size="0.04 0.04 0.03"/>
      </geometry>
      <material name="camera_gray">
        <color rgba="0.05 0.05 0.05 1"/>
      </material>
    </visual>

    <collision>
      <origin xyz="0 0 0" rpy="0 0 0"/>
      <geometry>
        <box size="0.04 0.04 0.03"/>
      </geometry>
    </collision>

    <inertial>
      <mass value="0.05"/>
      <origin xyz="0 0 0" rpy="0 0 0"/>
      <inertia ixx="1e-5" ixy="0" ixz="0" iyy="1e-5" iyz="0" izz="1e-5"/>
    </inertial>
  </link>

  <joint name="wrist_rgbd_camera_joint" type="fixed">
    <parent link="Link6"/>
    <child link="wrist_rgbd_camera_link"/>
    <origin xyz="0 0 0.08" rpy="0 1.5708 0"/>
  </joint>

  <gazebo reference="wrist_rgbd_camera_link">
    <material>Gazebo/Black</material>

    <sensor type="depth" name="wrist_rgbd_camera">
      <always_on>true</always_on>
      <update_rate>30.0</update_rate>

      <camera name="camera">
        <horizontal_fov>1.047</horizontal_fov>
        <image>
          <width>1280</width>
          <height>720</height>
          <format>R8G8B8</format>
        </image>
        <clip>
          <near>0.05</near>
          <far>5.0</far>
        </clip>
      </camera>

      <plugin name="wrist_rgbd_camera_controller" filename="libgazebo_ros_openni_kinect.so">
        <alwaysOn>true</alwaysOn>
        <updateRate>30.0</updateRate>

        <cameraName>wrist_rgbd</cameraName>
        <frameName>wrist_rgbd_camera_link</frameName>

        <imageTopicName>rgb/image_raw</imageTopicName>
        <cameraInfoTopicName>rgb/camera_info</cameraInfoTopicName>

        <depthImageTopicName>depth/image_raw</depthImageTopicName>
        <depthImageCameraInfoTopicName>depth/camera_info</depthImageCameraInfoTopicName>
        <pointCloudTopicName>depth/points</pointCloudTopicName>

        <pointCloudCutoff>0.05</pointCloudCutoff>
        <pointCloudCutoffMax>5.0</pointCloudCutoffMax>

        <hackBaseline>0.0</hackBaseline>
        <distortionK1>0.0</distortionK1>
        <distortionK2>0.0</distortionK2>
        <distortionK3>0.0</distortionK3>
        <distortionT1>0.0</distortionT1>
        <distortionT2>0.0</distortionT2>
      </plugin>
    </sensor>
  </gazebo>

</robot>
